Workbook

Sheet Coding Log
A1: CSC 808 Phase 2 Inductive QUAL Coding Log | Rambel Stone | April 2026
A2: Corpus: 47 documents | Codebook v1.0 | Constant comparative method | κ subsample: 16 docs, seed=808, Pass 1 / Pass 2 (≥14-day gap) | κ ≥ 0.70 required
A3: Entry # | B3: Doc # (registry) | C3: Document title (short) | D3: Year | E3: Source | F3: Artifact type | G3: Coding unit | H3: Page / section ref | I3: Passage text (extracted) | J3: Code 1 | K3: Code 2 | L3: Code 3 | M3: CRS flag | N3: Code 1 rationale | O3: Code 2 rationale | P3: Pass | Q3: κ subsample? | R3: Memo / analytic note | S3: source_detail | T3: artifact_type_review_flag | U3: kappa_status | V3: kappa_note
A4: 1 | B4: 39 | C4: SWGDE Overview: Artificial Intelligence Trends in Video Analysis (v1.0) | D4: 2021 | E4: SWGDE Video | F4: Published Document (AI-specific) PRIORITY | G4: Full document | H4: §3 Limitations, p.3 | I4: "not intended to state a position for or against the use of artificial intelligence...offered solely as an informational overview" | J4: ORG-01 | M4: CRS-02 | P4: Pass 1 | Q4: Yes | U4: in
A5: 2 | B5: 39 | C5: SWGDE Overview: Artificial Intelligence Trends in Video Analysis (v1.0) | D5: 2021 | E5: SWGDE Video | F5: Published Document (AI-specific) PRIORITY | G5: Full document | H5: §3 Limitations, p.3 | I5: "implemented only after consultation with legal personnel versed in the laws and rules applicable to the investigator's particular jurisdiction" | J5: ORG-06 | P5: Pass 1 | Q5: Yes | U5: in
A6: 3 | B6: 39 | C6: SWGDE Overview: Artificial Intelligence Trends in Video Analysis (v1.0) | D6: 2021 | E6: SWGDE Video | F6: Published Document (AI-specific) PRIORITY | G6: Full document | H6: §6.4, p.7 | I6: known examples of bias...any results/identification should be confirmed by a properly trained examiner before action is taken | J6: TEC-01 | M6: CRS-02 | P6: Pass 1 | Q6: Yes | U6: in
A7: 4 | B7: 39 | C7: SWGDE Overview: Artificial Intelligence Trends in Video Analysis (v1.0) | D7: 2021 | E7: SWGDE Video | F7: Published Document (AI-specific) PRIORITY | G7: Full document | H7: §7.4.1, p.1 | I7: "any results obtained through the use of ML-based data comparisons require human verification...before legal action is taken" | J7: CRS-02 | K7: TEC-02 | P7: Pass 1 | Q7: Yes | R7: "Cold read suggests possible reclassification. Consider CRS-02 as Code 1 with TEC-02 as Code 2. Verify in Pass 2." | U7: in
A8: 5 | B8: 39 | C8: SWGDE Overview: Artificial Intelligence Trends in Video Analysis (v1.0) | D8: 2021 | E8: SWGDE Video | F8: Published Document (AI-specific) PRIORITY | G8: Full document | H8: §7.4.3, p.11 | I8: "especially difficult for Computer Vision applications that adapt...algorithms developed for proprietary tools are unknown and require benchmarking" | J8: TEC-02 | K8: TEC-06 | P8: Pass 1 | Q8: Yes | U8: in
A9: 6 | B9: 39 | C9: SWGDE Overview: Artificial Intelligence Trends in Video Analysis (v1.0) | D9: 2021 | E9: SWGDE Video | F9: Published Document (AI-specific) PRIORITY | G9: Full document | H9: §7.4.3, p.11 | I9: "should provide limited statistical evaluation for false positives and negatives...results given at one point in time are able to be repeated" | J9: TEC-01 | M9: CRS-02 | P9: Pass 1 | Q9: Yes | U9: in
A10: 7 | B10: 39 | C10: SWGDE Overview: Artificial Intelligence Trends in Video Analysis (v1.0) | D10: 2021 | E10: SWGDE Video | F10: Published Document (AI-specific) PRIORITY | G10: Full document | H10: §10 History, p.15 | I10: 2.5-year revision cycle (Sept 2018 – Jan 2021), 9 editing sessions, no prescriptive output produced | J10: PRO-02 | P10: Pass 1 | Q10: Yes | R10: Flag column R (memo note) for entry 7: Dominant pattern: ORG-01 as structural frame; TEC-01/TEC-06 recurring in validation sections; CRS-02 consistent throughout. 2.5-year history with zero prescriptive output. | U10: in
A11: 8 | B11: 38 | C11: SWGDE Position on Facial Recognition and Facial Comparison Development and Com | D11: 2022 | E11: SWGDE Imaging | F11: Position Document (published) | G11: Full document | H11: §3 FRS def., p.1 | I11: "not meant to be a step-by-step guide...refer to FISWG" | J11: ORG-01 | N11: Strong | P11: Pass 1 | Q11: No | R11: Strong | U11: out
A12: 9 | B12: 38 | C12: SWGDE Position on Facial Recognition and Facial Comparison Development and Com | D12: 2022 | E12: SWGDE Imaging | F12: Position Document (published) | G12: Full document | H12: §4, p.2 | I12: "algorithm performance entirely dependent upon patterns...do not correlate to obvious anatomical features" | J12: TEC-06 | M12: CRS-01 | N12: Strong | P12: Pass 1 | R12: Strong
A13: 10 | B13: 38 | C13: SWGDE Position on Facial Recognition and Facial Comparison Development and Com | D13: 2022 | E13: SWGDE Imaging | F13: Position Document (published) | G13: Full document | H13: §4, p.2 | I13: "facial recognition candidate returns are not considered a positive identification...trained human adjudication" | J13: CRS-02 | N13: Provisional | P13: Pass 2 | R13: TEC-01 provisional
A14: 11 | B14: 38 | C14: SWGDE Position on Facial Recognition and Facial Comparison Development and Com | D14: 2022 | E14: SWGDE Imaging | F14: Position Document (published) | G14: Full document | H14: §4, p.2 | I14: "facial comparison does not provide positive identifications...standardized scale" | J14: TEC-01 | N14: Provisional | P14: Pass 1 | R14: TEC-03 provisional "?". NOTE reclassifying entry 11 from TEC-03 to CRS-02 in Pass 2. Note in memo column now. "Cold read suggests possible reclassification from TEC-03 to CRS-02 in Pass 2. Standardized scale is acknowledged but not specified this may be a language choice rather than unresolved technical consensus."
A15: 12 | B15: 38 | C15: SWGDE Position on Facial Recognition and Facial Comparison Development and Com | D15: 2022 | E15: SWGDE Imaging | F15: Position Document (published) | G15: Full document | H15: §4, p.2 | I15: "results must be reviewed by trained personnel...not the only basis for law enforcement action" | J15: ORG-06 | M15: CRS-02 | N15: Strong | P15: Pass 1 | R15: Strong
A16: 13 | B16: 38 | C16: SWGDE Position on Facial Recognition and Facial Comparison Development and Com | D16: 2022 | E16: SWGDE Imaging | F16: Position Document (published) | G16: Full document | H16: §6 History, p.3 | I16: Three consecutive Draft for Public Comment iterations (June 2021, Sept 2021, Jan 2022) | J16: PRO-01 | M16: CRS-01 | N16: Strong | P16: Pass 1 | R16: Strong
A17: 14 | B17: C1 | C17: NIST OSAC FSSB Meeting Agendas Public Sessions (2023, multiple quarters) | D17: 2023 | E17: NIST OSAC | F17: Meeting Agenda (Public) | G17: Full document | H17: Item 4, Task Groups | I17: Complete Task Group roster no AI or confidence measurement task group in FSSB governance | J17: ORG-07 | N17: Strong | P17: Pass 1 | Q17: No | R17: Strong confirmed across all 4 quarters: no AI TG added at any point in 2023 | U17: out
A18: 15 | B18: C1 | C18: NIST OSAC FSSB Meeting Agendas Public Sessions (2023, multiple quarters) | D18: 2023 | E18: NIST OSAC | F18: Meeting Agenda (Public) | G18: Full document | H18: Standards pipeline, Day 2 | I18: Full standards pipeline no AI standards in registry review, petition, or open comment | J18: ORG-07 | N18: Strong | P18: Pass 1 | R18: Strong confirmed cross-quarter: no AI standards in pipeline Q1–Q4
A19: 16 | B19: C1 | C19: NIST OSAC FSSB Meeting Agendas Public Sessions (2023, multiple quarters) | D19: 2023 | E19: NIST OSAC | F19: Meeting Agenda (Public) | G19: Full document | H19: Item 6c-iv, D/M SAC | I19: "Digital/Multimedia Technical Guidance Request [Vote]" only D/M action item in full year | J19: ORG-03 | N19: Provisional | P19: Pass 1 | R19: Provisional "?" content of request not visible. Still provisional "?". This cannot be resolved without knowing what the vote covered. Hold at ORG-03 "?" until C5 or other C1 documents provide context.
A20: 17 | B20: C1 | C20: NIST OSAC FSSB Meeting Agendas Public Sessions (2023, multiple quarters) | D20: 2023 | E20: NIST OSAC | F20: Meeting Agenda (Public) | G20: Full document | H20: OPO Item 3 | I20: R&D Needs Update recurring information-only item, no D/M or AI escalation visible | J20: ORG-07 | N20: Provisional | P20: Pass 1 | R20: Provisional "?" cross-document support needed from C5. retain ORG-07 but note in memo that entry 22 provides the stronger empirical confirmation of this pattern. Entries 17 and 22 together form one finding, not two independent findings.
A21: 18 | B21: C1 | C21: NIST OSAC FSSB Meeting Agendas Public Sessions (2023, multiple quarters) | D21: 2023 | E21: NIST OSAC | F21: Meeting Agenda (Public) | G21: Full document | H21: Item 24, Day 2 | I21: "Interpretation Scales FSSB Discussion: Chemistry: Trace Evidence, Physics/Pattern" Digital/Multimedia excluded | J21: ORG-05 | N21: Strong | P21: Pass 2 | R21: Strong on ORG-05; ORG-03 provisional "?". Pass 2, consider dropping ORG-03 from this entry and keeping ORG-05 only unless you find evidence the D/M exclusion was a priority decision rather than a scope decision.
A22: 19 | B22: 1 | C22: NIST AI RMF Development Public Comments Received During RFC Period | D22: 2023 | E22: NIST AI | F22: Public Comment Record | G22: Full document | H22: Section Level | I22: NIST AI RMF RFC public comment record inaccessible EO 14110 rescinded Jan 20 2025; NIST site search returns no results; associated comment archive delisted | J22: PRO-02 | K22: ORG-05 | N22: Possible Emerging | P22: Pass 1 | Q22: No | R22: Entry 19 (EO 14110 rescission rendering NIST AI RMF RFC inaccessible) does not fit cleanly into any existing code. PRO-02 + ORG-05 captures it partially but misses the specifically political and external nature of the barrier. This is still a candidate for EMER-01. The question is whether this pattern recurs. If you find other instances of AI governance records being rendered inaccessible by political action in your remaining 42 documents, activate EMER-01. If entry 19 remains the only instance, it is better described as an unusual PRO-02 than as a new category. Hold EMER-01 do not activate yet. | U22: out
A23: 20 | B23: 16 | C23: NIST OSAC Annual Reports Digital/Multimedia SAC (2020, 2021, 2022, 2023) [consolidated from orig. #16–19] | D23: 2020–2023 | E23: NIST OSAC | F23: Annual Report / Organizational Newsletter | G23: Full document | H23: Section Level | I23: Document-level access finding | J23: ORG-05 | N23: Strong | P23: Pass 1 | R23: OSAC annual reports not consistently published or archived 2020 and 2022 inaccessible. Institutional transparency gap limits external accountability for Digital/Multimedia standards governance.
A24: 21 | B24: 16 | C24: NIST OSAC Annual Reports Digital/Multimedia SAC (2020, 2021, 2022, 2023) [consolidated from orig. #16–19] | D24: 2020–2023 | E24: NIST OSAC | F24: Annual Report / Organizational Newsletter | G24: Full document | H24: Section Level | I24: table"Digital Evidence +2 Published (1st SWGDE documents!)" FY23 first SWGDE entry in 9 years | J24: ORG-05 | N24: Strong | P24: Pass 1
A25: 22 | B25: 16 | C25: NIST OSAC Annual Reports Digital/Multimedia SAC (2020, 2021, 2022, 2023) [consolidated from orig. #16–19] | D25: 2020–2023 | E25: NIST OSAC | F25: Annual Report / Organizational Newsletter | G25: Full document | H25: Section Level | I25: "There are no research and development needs identified by the Digital Evidence Subcommittee" | J25: ORG-07 | N25: Strongest ORG-07 in corpus | P25: Pass 1 | Q25: No | U25: out
A26: 23 | B26: 16 | C26: NIST OSAC Annual Reports Digital/Multimedia SAC (2020, 2021, 2022, 2023) [consolidated from orig. #16–19] | D26: 2020–2024 | E26: NIST OSAC | F26: Annual Report / Organizational Newsletter | G26: Full document | H26: Section Level | I26: ANSI/ASTM E3016-18 confidence standard pending OSAC registry acceptance since 2018 (6+ years) | J26: PRO-02 | K26: PRO-06 | N26: Strongest PRO-02 in corpus | P26: Pass 1 | R26: Action: Recoded entry 23 from PRO-02 to PRO-06, or assign both. PRO-06 is more precise here because the standard exists and is published the failure is in the adoption pathway between the SDO and the governance registry, which is a coordination gap rather than a process stall. Write a decision log entry explaining this distinction.
A27: 24 | B27: 16 | C27: NIST OSAC Annual Reports Digital/Multimedia SAC (2020, 2021, 2022, 2023) [consolidated from orig. #16–19] | D27: 2020–2025 | E27: NIST OSAC | F27: Annual Report / Organizational Newsletter | G27: Full document | H27: Section Level | I27: Generative AI tools reference document informational only, no prescriptive requirements | J27: ORG-01 | N27: Strong | P27: Pass 1 | Q27: Yes | U27: in
A28: 25 | B28: 16 | C28: NIST OSAC Annual Reports Digital/Multimedia SAC (2020, 2021, 2022, 2023) [consolidated from orig. #16–19] | D28: 2020–2026 | E28: NIST OSAC | F28: Annual Report / Organizational Newsletter | G28: Full document | H28: Section Level | I28: "Is this a Deepfake?" both versions listed as "being updated," no publication date | J28: PRO-03 | N28: Strong | P28: Pass 1
A29: =IF(I29<>"",ROW()-3,"") -> 26 | B29: 42 | C29: SWGDE Best Practices for Digital Evidence Acquisition from Cloud Service Providers (v1.0) | D29: 2020 | E29: SWGDE Forensics | F29: Draft Released for Comment | G29: Full document | H29: §3 Limitations, p.4 | I29: "Due to the vast number of emerging platforms and cloud service providers, it is not possible to establish a precise set of procedures to cover every situation...This document identifies the high-level considerations and steps for the collection of cloud based digital evidence." | J29: ORG-01 | N29: Strong explicit scope exclusion; precision procedures deferred to examiner judgment; no confidence metric or AI-specific content follows from this framing | P29: Pass 1 | Q29: Yes | U29: in
A30: =IF(I30<>"",ROW()-3,"") -> 27 | B30: 42 | C30: SWGDE Best Practices for Digital Evidence Acquisition from Cloud Service Providers (v1.0) | D30: 2020 | E30: SWGDE Forensics | F30: Draft Released for Comment | G30: Full document | H30: §3 Limitations, p.4 | I30: "Guidance in this document is not meant to replace legal guidance from a responsible legal professional, nor is it meant to cover every conceivable situation." | J30: ORG-06 | N30: Legal constraint as structural ceiling on guidance specificity mirrors Doc #38 dominant pattern; legal deference prevents prescriptive output | P30: Pass 1 | Q30: Yes | U30: in
A31: =IF(I31<>"",ROW()-3,"") -> 28 | B31: 42 | C31: SWGDE Best Practices for Digital Evidence Acquisition from Cloud Service Providers (v1.0) | D31: 2020 | E31: SWGDE Forensics | F31: Draft Released for Comment | G31: Full document | H31: §9 Steps After Acquisition, p.10 | I31: "Compute and record hash values for the acquired data. If a provider has digitally signed their production or provided hash values, verify the signature or hash values." | J31: TEC-03 | M31: CRS-02 | N31: Hash verification is the only quantifiable integrity mechanism in the document a procedural integrity check, not a confidence metric; contingent on provider cooperation | P31: Pass 1 | Q31: Yes | U31: in
A32: =IF(I32<>"",ROW()-3,"") -> 29 | B32: 42 | C32: SWGDE Best Practices for Digital Evidence Acquisition from Cloud Service Providers (v1.0) | D32: 2020 | E32: SWGDE Forensics | F32: Draft Released for Comment | G32: Full document | H32: §6.2 / §8 During Acquisition, pp.6, 9 | I32: "If the cloud service does not provide an export tool, the collector should document specific steps taken or tools utilized...If all methods fail, consider screen captures or photographs of the relevant data." | J32: TEC-02 | K32: PRO-02 | N32: Validation methodology absent; fallback to screen captures/photographs as last resort no validated acquisition standard exists for heterogeneous cloud environments | O32: Process stall document cannot converge on prescriptive acquisition protocol; provider environment heterogeneity prevents standardization | P32: Pass 1 | Q32: Yes | U32: in
A33: =IF(I33<>"",ROW()-3,"") -> 30 | B33: 42 | C33: SWGDE Best Practices for Digital Evidence Acquisition from Cloud Service Providers (v1.0) | D33: 2020 | E33: SWGDE Forensics | F33: Draft Released for Comment | G33: Full document | H33: §10 History, p.11 | I33: Draft June 2019 → public comment period → no edits following comment period → approved September 2019 → re-voted final publication September 2020. Zero substantive changes after public comment. | J33: PRO-01 | N33: Multi-stage public comment process produced zero substantive changes no confidence measurement content added at any revision stage across 14-month publication cycle | P33: Pass 1 | Q33: Yes | R33: Doc 42 dominant pattern: ORG-01 + ORG-06 co-occurrence in §3 now confirmed third consecutive SWGDE document with this dual exclusion opening (Docs #36, #38, #42). Hash verification (TEC-03/CRS-02) in §9 is only integrity mechanism contingent on provider cooperation, reinforcing ORG-02 resource constraint theme. PRO-01 history: zero edits after public comment mirrors Doc #38 three-iteration pattern. Leanest codeable document in corpus almost entirely legal/procedural scaffolding. | U33: in
A34: 31 | B34: 36 | C34: SWGDE Best Practices for On-Scene ID, Seizure & Preservation of IoT Devices (22-F-001-1.0) | D34: 2022 | E34: SWGDE Forensics | F34: Draft Released for Comment | G34: Full document | H34: §1 Purpose / §2 Scope, pp.2 | I34: "not intended to be a training manual or a specific operating procedure...not all-inclusive" procedural guidance scoped to on-scene only; cloud, analytics, and AI tool validation explicitly excluded | J34: ORG-01 | N34: Strong explicit scope exclusion language limits document to field identification/seizure; AI tool output validation and confidence measurement are outside stated scope | P34: Pass 1 | Q34: Yes | R34: Doc 36 dominant pattern: ORG-01 (scope exclusion) as primary frame AI/confidence measurement excluded by design, not omission. TEC-01/TEC-02 present in preservation/collection sections without resolution. ORG-02 + PRO-02 co-occur in §9 confirming resource-process barrier dyad. Zero prescriptive confidence output. Compare with Doc #39 (informational positioning) and Doc #38 (legal constraint framing) Doc 36 adds a third SWGDE exclusion logic: operational scope. | U34: in
A35: 32 | B35: 36 | C35: SWGDE Best Practices for On-Scene ID, Seizure & Preservation of IoT Devices (22-F-001-1.0) | D35: 2022 | E35: SWGDE Forensics | F35: Draft Released for Comment | G35: Full document | H35: §7 Collection, pp.7–8 | I35: Artifact/Data Spoliation "Specific Considerations/Cautions (Instances where probative data exists in volatile memory only or where data overwrites or appends in a finite storage setting)" no error rate or confidence metric specified | J35: TEC-01 | M35: CRS-02 | N35: Acknowledges data integrity risk (volatile memory, finite storage overwrite) but provides no quantitative confidence metric or error rate gap identified, not addressed | P35: Pass 1 | Q35: Yes | U35: in
A36: 33 | B36: 36 | C36: SWGDE Best Practices for On-Scene ID, Seizure & Preservation of IoT Devices (22-F-001-1.0) | D36: 2022 | E36: SWGDE Forensics | F36: Draft Released for Comment | G36: Full document | H36: §8 Preservation, pp.9 | I36: "Just as the integrity of the data of more traditional devices needs to be preserved through write-blocking or other means, IoT devices and associated applications similarly need information protected and preserved" analogical framing, no IoT-specific validation protocol specified | J36: TEC-02 | N36: Recognizes that IoT preservation requires equivalent rigor to traditional digital forensics but offers no IoT-specific validation methodology gap acknowledged via analogy without resolution | P36: Pass 1 | Q36: Yes | U36: in
A37: 34 | B37: 36 | C37: SWGDE Best Practices for On-Scene ID, Seizure & Preservation of IoT Devices (22-F-001-1.0) | D37: 2022 | E37: SWGDE Forensics | F37: Draft Released for Comment | G37: Full document | H37: §9 Other Considerations, pp.9 | I37: "One of the major challenges in data acquisition from IoT devices is the lack of available training, tools, research documents, and collection procedures. Manufacturers may be reluctant to provide assistance..." | J37: ORG-02 | K37: PRO-02 | N37: Resource constraint explicit acknowledgment of tool/training/documentation gap as primary barrier to forensic capability in this domain | O37: Process stall absence of validated collection procedures is framed as current state, not as a development roadmap; no timeline or prescription for resolution | P37: Pass 1 | Q37: Yes | R37: Doc 36 dominant pattern: ORG-01 (scope exclusion) as primary frame AI/confidence measurement excluded by design, not omission. TEC-01/TEC-02 present in preservation/collection sections without resolution. ORG-02 + PRO-02 co-occur in §9 confirming resource-process barrier dyad. Zero prescriptive confidence output. Compare with Doc #39 (informational positioning) and Doc #38 (legal constraint framing) Doc 36 adds a third SWGDE exclusion logic: operational scope. | U37: in
A38: 35 | B38: 34 | C38: SWGDE Training Guidelines for Video/Image Analysis and Photography | D38: 2019 | E38: SWGDE | F38: Training Guidelines | G38: Full document | H38: §1 Purpose §4 Limitations | I38: "provide guidelines and recommendations…program should demonstrate and document the training selected is adequate to ensure competency" | J38: ORG-01 | K38: — | L38: CRS-02 | N38: Document-level pattern: ORG-01 (scope exclusion) + TEC-01 (measurement complexity) are co-dominant. TEC-02 present at §5. PRO-01 confirmed via revision history. No AI-specific content (publication date 2016). CRS-02 flags cluster around §3, §9, and §10.5/10.7 competency/proficiency definitions acknowledge measurement without operationalizing it. | Scope exclusion | [code_3]: "Adequate to ensure competency" confidence-adjacent, no quantitative grounding | P38: Pass 1 | Q38: Yes | U38: in
A39: 36 | B39: 34 | C39: SWGDE Training Guidelines for Video/Image Analysis and Photography | D39: 2019 | E39: SWGDE | F39: Training Guidelines | G39: Full document | H39: §3 Terminology | I39: Competency = "evaluation of knowledge and ability…prior to independent completion"; Proficiency = "evaluation of quality of performance" | J39: TEC-01 | K39: — | L39: — | N39: Document-level pattern: ORG-01 (scope exclusion) + TEC-01 (measurement complexity) are co-dominant. TEC-02 present at §5. PRO-01 confirmed via revision history. No AI-specific content (publication date 2016). CRS-02 flags cluster around §3, §9, and §10.5/10.7 competency/proficiency definitions acknowledge measurement without operationalizing it. | Measurement complexity | P39: Pass 1 | Q39: Yes | U39: in
A40: 37 | B40: 34 | C40: SWGDE Training Guidelines for Video/Image Analysis and Photography | D40: 2019 | E40: SWGDE | F40: Training Guidelines | G40: Full document | H40: §9 Training Evaluation & Documentation | I40: "A means of testing an individual's competency…ongoing proficiency…a schedule for the completion of testing" | J40: TEC-01 | K40: — | L40: CRS-02 | N40: Document-level pattern: ORG-01 (scope exclusion) + TEC-01 (measurement complexity) are co-dominant. TEC-02 present at §5. PRO-01 confirmed via revision history. No AI-specific content (publication date 2016). CRS-02 flags cluster around §3, §9, and §10.5/10.7 competency/proficiency definitions acknowledge measurement without operationalizing it. | Measurement complexity | [code_3]: Competency testing mandated as process requirement no threshold, rubric, or quantitative standard | P40: Pass 1 | Q40: Yes | U40: in
...

Sheet Document Tracker
A1: Phase 2 Document Tracker — Coding Progress by Document
A2: Update 'Status' and 'Passages coded' after each document. Flag κ subsample docs for Pass 2 scheduling.
A3: Doc # | B3: Title (short) | C3: Year | D3: Source | E3: Artifact type | F3: Coding unit | G3: κ subsample? | H3: Status | I3: Passages coded | J3: Memo written?
A4: 39 | B4: SWGDE Overview: Artificial Intelligence Trends in Video Analysis (v1.0) | C4: 2021 | D4: SWGDE Video | E4: Published Document (AI-specific) — PRIORITY | F4: Full document | G4: Yes | H4: Pass 1 complete | I4: 7 | J4: Yes
A5: 38 | B5: SWGDE Position on Facial Recognition and Facial Comparison — Development and Com | C5: 2022 | D5: SWGDE Imaging | E5: Position Document (published) | F5: Full document | G5: Yes | H5: Pass 1 complete | I5: 6 | J5: Yes
A6: C1 | B6: NIST OSAC FSSB Meeting Agendas — Public Sessions (2023, multiple quarters) | C6: 2023 | D6: NIST OSAC | E6: Meeting Agenda (Public) | F6: Full document | G6: Yes | H6: Pass 1 complete | I6: 5 | J6: Yes
A7: 1 | B7: NIST AI RMF Development — Public Comments Received During RFC Period | C7: 2023 | D7: NIST AI | E7: Public Comment Record | F7: Full document | G7: No | H7: Pass 1 complete | I7: 0 | J7: Yes
A8: 16 | B8: NIST OSAC Annual Reports — Digital/Multimedia SAC (2020, 2021, 2022, 2023) [cons | C8: 2020–2023 | D8: NIST OSAC | E8: Annual Report / Organizational Newsletter | F8: Full document | G8: Yes | H8: Pass 1 complete | I8: 6 | J8: Yes
A9: 2 | B9: NIST AI RMF Stakeholder Input Summary (Workshop Ancillary Documentation) | C9: 2023 | D9: NIST AI | E9: Public Comment Record | F9: Full document | G9: No | H9: Pass 1 complete | J9: No
A10: 3 | B10: NIST AI 600-1 (Generative AI) — Public Comment Summary | C10: 2024 | D10: NIST AI | E10: Public Comment Record | F10: Full document | G10: Yes | H10: Pass 1 complete | J10: No
A11: 4 | B11: NIST CSF 2.0 — Public Comment Analysis Report | C11: 2024 | D11: NIST CSF | E11: News Release / Development Process Surrogate, | F11: Full document | G11: Yes | H11: Pass 2 complete | I11: 7 | J11: Yes
A12: 5 | B12: NIST IR 8354 (Digital Investigation Techniques) — Public Comment Period Record | C12: 2022 | D12: NIST CFTT | E12: Public Comment Record | F12: Full document | G12: No | H12: Pass 1 complete | I12: 0 | J12: Yes
A13: 6 | B13: NIST SP 800-53 Rev 5 — Comment Disposition Report | C13: 2022 | D13: NIST SP 800 | E13: Comment Disposition Report | F13: AI- and confidence-relevant comment threads only (large-volume CDR — apply within-document sampling) | G13: Yes | H13: Pass 1 complete | I13: 9 | J13: Yes
A14: 7 | B14: NIST SP 800-61 Rev 3 (Incident Response) — Public Comment Record | C14: 2024 | D14: NIST SP 800 | E14: Public Comment Record | F14: Full document | G14: Yes | H14: Pass 1 complete | I14: 6 | J14: Yes
A15: 8 | B15: NIST SP 800-92 Rev 1 (Log Management) — Initial Public Draft Comment Summary | C15: 2023 | D15: NIST SP 800 | E15: Public Comment Record | F15: Full document | G15: No | H15: Pass 1 complete | J15: No
A16: 9 | B16: NIST CSF 2.0 — Change Log and Revision History (v1.1 to v2.0) | C16: 2024 | D16: NIST CSF | E16: Revision History | F16: Revision history / change log section only (embedded in versioned PDF) | G16: No | H16: Pass 1 complete | J16: No
A17: 10 | B17: NIST AI 100-2 (Adversarial ML) — Draft to Final Comment Disposition | C17: 2024 | D17: NIST AI | E17: Comment Disposition Report | F17: Full document | G17: Yes | H17: Pass 1 complete | J17: Yes
A18: 11 | B18: NIST CFTT Mobile Spec v3.1 — Change Summary from v3.0 | C18: 2021 | D18: NIST CFTT | E18: Revision History (embedded) | F18: Revision history / change log section only (embedded in versioned PDF) | G18: No | H18: Pass 1 complete | J18: No
A19: 12 | B19: NIST CFTT Mobile Spec v3.2 — Change Summary from v3.1 | C19: 2024 | D19: NIST CFTT | E19: Revision History (embedded) | F19: Revision history / change log section only (embedded in versioned PDF) | G19: No | H19: Pass 1 complete | J19: No
A20: 13 | B20: NIST IR 8596 (Cyber AI Profile) — Preliminary Draft Workshop Summary | C20: 2025 | D20: NIST AI | E20: Working Group Notes / Workshop Summary | F20: Full document | G20: Yes | H20: Pass 1 complete | I20: 0 | J20: No
A21: 14 | B21: NIST AI 100-4 (Synthetic Content) — Public Workshop and Stakeholder Feedback | C21: 2025 | D21: NIST AI | E21: Public Comment Record | F21: Full document | G21: Yes | H21: Pass 1 complete | J21: No
A22: 15 | B22: NIST OpenMFC 2020-2021 Evaluation Proceedings and Participant Feedback | C22: 2022 | D22: NIST AI | E22: Working Group Notes / Evaluation Proceedings | F22: Full document | G22: No | H22: Pass 1 complete | I22: 10 | J22: Yes | L22: Remaining work: Tier 1 κ documents #21, #25, #26, #28 only. Saturation sampling is complete.
A23: 20 | B23: NIST SP 800-218A (Secure Dev for GenAI) — Draft Comment Disposition | C23: 2025 | D23: NIST SP 800 | E23: Public Comment Record | F23: Full document | G23: No | H23: Pass 1 complete | I23: 0 | J23: No
A24: 21 | B24: SWGDE Best Practices for Digital Forensic Video Analysis (18-V-001-2.0) — Revisi | C24: 2025 | D24: SWGDE Video | E24: Revision History (embedded) | F24: Revision history / change log section only (embedded in versioned PDF) | G24: Yes | H24: Pass 2 complete | I24: 11 | J24: Yes
A25: 22 | B25: SWGDE Best Practices for Computer Forensic Examinations (18-F-001-2.0) — Comment | C25: 2025 | D25: SWGDE Forensics | E25: Revision History (embedded) | F25: Revision history / change log section only (embedded in versioned PDF) | G25: No | H25: Pass 1 complete | J25: No
A26: 23 | B26: SWGDE Legal and Scientific Support: Admissibility of Image Examinations (23-I-00 | C26: 2025 | D26: SWGDE Imaging | E26: Draft Released for Comment | F26: Full document | G26: No | H26: Pass 1 complete | J26: No
A27: 24 | B27: SWGDE Guidelines for Forensic Image Analysis (16-I-002-2.0) — Revision Summary v | C27: 2025 | D27: SWGDE Imaging | E27: Revision History (embedded) | F27: Revision history / change log section only (embedded in versioned PDF) | G27: No | H27: Pass 1 complete | J27: No
A28: 25 | B28: SWGDE Core Competencies for Mobile Device Forensics (12-F-003-2.0) — Five-Year R | C28: 2025 | D28: SWGDE Forensics | E28: Revision History (embedded) | F28: Revision history / change log section only (embedded in versioned PDF) | G28: Yes | H28: Pass 2 complete | I28: 10 | J28: Yes
A29: 26 | B29: SWGDE Guidelines for Forensic Image Analysis (16-I-002-2.0 Draft) — Draft for Pu | C29: 2024 | D29: SWGDE Imaging | E29: Draft Released for Comment | F29: Full document | G29: Yes | H29: Pass 1 complete | I29: 9 | J29: Yes
A30: 27 | B30: SWGDE Model Standard Operation Procedures (12-F-001-3.0) — Draft for Public Comm | C30: 2024 | D30: SWGDE Forensics | E30: Draft Released for Comment | F30: Full document | G30: No | H30: Pass 1 complete | J30: No
A31: 28 | B31: SWGDE Best Practices for Digital Forensic Video Analysis (18-V-001-1.1) — Archiv | C31: 2024 | D31: SWGDE Video | E31: Archived Version / Revision History | F31: Revision history / change log section only (embedded in versioned PDF) | G31: Yes | H31: Pass 2 complete | I31: 8 | J31: Yes
A32: 29 | B32: SWGDE Core Competencies for Digital Forensics (23-F-007-1.1) — Archived with Cha | C32: 2024 | D32: SWGDE Forensics | E32: Archived Version / Revision History | F32: Revision history / change log section only (embedded in versioned PDF) | G32: No | H32: Pass 1 complete | J32: No
A33: 30 | B33: SWGDE Core Competencies for Digital Forensics (12-F-006-2.0) — Published Final | C33: 2024 | D33: SWGDE Forensics | E33: Revision History (embedded) | F33: Revision history / change log section only (embedded in versioned PDF) | G33: No | H33: Pass 1 complete | J33: No
A34: 31 | B34: SWGDE Best Practices for Computer Forensic Acquisitions (17-F-002-2.0) — Revisio | C34: 2023 | D34: SWGDE Forensics | E34: Archived Version / Revision History | F34: Revision history / change log section only (embedded in versioned PDF) | G34: No | H34: Pass 1 complete | J34: No
A35: 32 | B35: SWGDE Technical Notes on FFmpeg for Forensic Audio Examination (23-A-001-1.0) | C35: 2023 | D35: SWGDE Audio | E35: Published Document (technical notes) | F35: Full document | G35: No | H35: Pass 1 complete | J35: No
A36: 33 | B36: SWGDE Test Method for Bluetooth Module Extraction (20-F-003-1.2) — Draft for Com | C36: 2023 | D36: SWGDE Forensics | E36: Draft Released for Comment | F36: Full document | G36: No | H36: Pass 1 complete | J36: No
A37: 34 | B37: SWGDE Training Guidelines for Video/Image Analysis and Photography (15-M-001-1.2 | C37: 2023 | D37: SWGDE Video | E37: Draft Released for Comment | F37: Full document | G37: Yes | H37: Pass 1 complete | I37: 6 | J37: Yes
A38: 35 | B38: SWGDE Best Practices for Video Authentication (23-V-001-1.2) — Revision History | C38: 2023 | D38: SWGDE Video | E38: Revision History (embedded) | F38: Revision history / change log section only (embedded in versioned PDF) | G38: No | H38: Pass 1 complete | J38: No
A39: 36 | B39: SWGDE Best Practices for On-Scene Identification, Seizure, and Preservation of I | C39: 2022 | D39: SWGDE Forensics | E39: Draft Released for Comment | F39: Full document | G39: Yes | H39: Pass 1 complete | I39: 4 | J39: Yes
A40: 37 | B40: SWGDE Introduction to Testimony in Digital and Multimedia Forensics (22-Q-001-1. | C40: 2022 | D40: SWGDE Quality | E40: Archived Version / Revision History | F40: Revision history / change log section only (embedded in versioned PDF) | G40: No | H40: Pass 1 complete | J40: No
...

Sheet Memo Log
A1: Phase 2 Analytic Memo Log — Write after every 5 documents coded
A2: Memos document emerging patterns, code boundary decisions, unexpected findings, and tensions between codes. Required for reflexivity audit trail.
A3: Memo # | B3: Date | C3: After doc(s) # | D3: Emerging patterns / observations | E3: Code boundary decisions made | F3: Tensions / contradictions noted | G3: Action items (code changes, new EMER codes, etc.) | H3: Observations | I3: Document
A4: 1 | B4: 46122 | D4: Flag column R (memo note) for entry 7: Dominant pattern: ORG-01 as structural frame; TEC-01/TEC-06 recurring in validation sections; CRS-02 consistent throughout. 2.5-year history with zero prescriptive output. Compare against other SWGDE docs — is informational-only positioning a recurring organizational strategy? | E4: Flag column R (memo note) for entry 7: Dominant pattern: ORG-01 as structural frame; TEC-01/TEC-06 recurring in validation sections; CRS-02 consistent throughout. 2.5-year history with zero prescriptive output. Compare against other SWGDE docs — is informational-only positioning a recurring organizational strategy? | F4: Flag column R (memo note) for entry 7: Dominant pattern: ORG-01 as structural frame; TEC-01/TEC-06 recurring in validation sections; CRS-02 consistent throughout. 2.5-year history with zero prescriptive output. Compare against other SWGDE docs — is informational-only positioning a recurring organizational strategy? | G4: Flag column R (memo note) for entry 7: Dominant pattern: ORG-01 as structural frame; TEC-01/TEC-06 recurring in validation sections; CRS-02 consistent throughout. 2.5-year history with zero prescriptive output. Compare against other SWGDE docs — is informational-only positioning a recurring organizational strategy?
A5: 2 | B5: 46122 | C5: 38 | D5: Document #38 dominant pattern: ORG-06 (legal/admissibility concern) as primary structural mechanism — distinct from #39's ORG-01 framing. Both documents result in zero prescriptive confidence metrics but via different organizational logics. #38 knows measurement is needed ("standardized scale") but cannot specify it. Emerging cross-document pattern: SWGDE acknowledges AI output limitations consistently but organizational and legal constraints prevent measurement prescription. Compare with NIST documents for organizational barrier contrast. | E5: Document #38 dominant pattern: ORG-06 (legal/admissibility concern) as primary structural mechanism — distinct from #39's ORG-01 framing. Both documents result in zero prescriptive confidence metrics but via different organizational logics. #38 knows measurement is needed ("standardized scale") but cannot specify it. Emerging cross-document pattern: SWGDE acknowledges AI output limitations consistently but organizational and legal constraints prevent measurement prescription. Compare with NIST documents for organizational barrier contrast. | F5: Document #38 dominant pattern: ORG-06 (legal/admissibility concern) as primary structural mechanism — distinct from #39's ORG-01 framing. Both documents result in zero prescriptive confidence metrics but via different organizational logics. #38 knows measurement is needed ("standardized scale") but cannot specify it. Emerging cross-document pattern: SWGDE acknowledges AI output limitations consistently but organizational and legal constraints prevent measurement prescription. Compare with NIST documents for organizational barrier contrast. | G5: Document #38 dominant pattern: ORG-06 (legal/admissibility concern) as primary structural mechanism — distinct from #39's ORG-01 framing. Both documents result in zero prescriptive confidence metrics but via different organizational logics. #38 knows measurement is needed ("standardized scale") but cannot specify it. Emerging cross-document pattern: SWGDE acknowledges AI output limitations consistently but organizational and legal constraints prevent measurement prescription. Compare with NIST documents for organizational barrier contrast.
A6: 3 | B6: 46122 | D6: C1 dominant pattern: ORG-07 confirmed cross-quarter — AI is entirely absent from FSSB governance machinery across all four 2023 quarters at the task group, standards pipeline, and SAC action-item levels. December interpretation scales discussion (entry 18) is most significant finding — governance-level confidence measurement discussion explicitly scoped to exclude Digital/Multimedia SAC. Emerging cross-corpus pattern: OSAC institutional structure does not yet have a mechanism for AI governance in the digital forensics domain as of end of 2023. Compare with NIST AI RMF documents (#1, #3) for organizational contrast. | E6: C1 dominant pattern: ORG-07 confirmed cross-quarter — AI is entirely absent from FSSB governance machinery across all four 2023 quarters at the task group, standards pipeline, and SAC action-item levels. December interpretation scales discussion (entry 18) is most significant finding — governance-level confidence measurement discussion explicitly scoped to exclude Digital/Multimedia SAC. Emerging cross-corpus pattern: OSAC institutional structure does not yet have a mechanism for AI governance in the digital forensics domain as of end of 2023. Compare with NIST AI RMF documents (#1, #3) for organizational contrast. | F6: C1 dominant pattern: ORG-07 confirmed cross-quarter — AI is entirely absent from FSSB governance machinery across all four 2023 quarters at the task group, standards pipeline, and SAC action-item levels. December interpretation scales discussion (entry 18) is most significant finding — governance-level confidence measurement discussion explicitly scoped to exclude Digital/Multimedia SAC. Emerging cross-corpus pattern: OSAC institutional structure does not yet have a mechanism for AI governance in the digital forensics domain as of end of 2023. Compare with NIST AI RMF documents (#1, #3) for organizational contrast. | G6: C1 dominant pattern: ORG-07 confirmed cross-quarter — AI is entirely absent from FSSB governance machinery across all four 2023 quarters at the task group, standards pipeline, and SAC action-item levels. December interpretation scales discussion (entry 18) is most significant finding — governance-level confidence measurement discussion explicitly scoped to exclude Digital/Multimedia SAC. Emerging cross-corpus pattern: OSAC institutional structure does not yet have a mechanism for AI governance in the digital forensics domain as of end of 2023. Compare with NIST AI RMF documents (#1, #3) for organizational contrast.
A7: 4 | B7: 46122 | D7: Document #1 — access failure finding: EO 14110 rescission January 2025 rendered NIST AI RMF RFC public comment archive inaccessible. This is the only corpus document lost to governmental policy reversal rather than organizational scope decision or technical barrier. Coded PRO-02 + ORG-05 at document level. This finding has direct relevance to P2: even where AI governance standards development processes produced public records, those records are institutionally fragile and subject to political disruption. Cross-reference with CRS-04 (temporal marker — AI emergence period) — the 2020–2025 window is not just a period of AI standards development but also of AI governance instability at the federal level. Consider whether this warrants an emergent code: EMER-01 — Governmental policy reversal as process barrier (distinct from PRO-02 in that it is external and political rather than internal and procedural). | E7: Document #1 — access failure finding: EO 14110 rescission January 2025 rendered NIST AI RMF RFC public comment archive inaccessible. This is the only corpus document lost to governmental policy reversal rather than organizational scope decision or technical barrier. Coded PRO-02 + ORG-05 at document level. This finding has direct relevance to P2: even where AI governance standards development processes produced public records, those records are institutionally fragile and subject to political disruption. Cross-reference with CRS-04 (temporal marker — AI emergence period) — the 2020–2025 window is not just a period of AI standards development but also of AI governance instability at the federal level. Consider whether this warrants an emergent code: EMER-01 — Governmental policy reversal as process barrier (distinct from PRO-02 in that it is external and political rather than internal and procedural). | F7: Document #1 — access failure finding: EO 14110 rescission January 2025 rendered NIST AI RMF RFC public comment archive inaccessible. This is the only corpus document lost to governmental policy reversal rather than organizational scope decision or technical barrier. Coded PRO-02 + ORG-05 at document level. This finding has direct relevance to P2: even where AI governance standards development processes produced public records, those records are institutionally fragile and subject to political disruption. Cross-reference with CRS-04 (temporal marker — AI emergence period) — the 2020–2025 window is not just a period of AI standards development but also of AI governance instability at the federal level. Consider whether this warrants an emergent code: EMER-01 — Governmental policy reversal as process barrier (distinct from PRO-02 in that it is external and political rather than internal and procedural). | G7: Document #1 — access failure finding: EO 14110 rescission January 2025 rendered NIST AI RMF RFC public comment archive inaccessible. This is the only corpus document lost to governmental policy reversal rather than organizational scope decision or technical barrier. Coded PRO-02 + ORG-05 at document level. This finding has direct relevance to P2: even where AI governance standards development processes produced public records, those records are institutionally fragile and subject to political disruption. Cross-reference with CRS-04 (temporal marker — AI emergence period) — the 2020–2025 window is not just a period of AI standards development but also of AI governance instability at the federal level. Consider whether this warrants an emergent code: EMER-01 — Governmental policy reversal as process barrier (distinct from PRO-02 in that it is external and political rather than internal and procedural).
A8: 5 | B8: 46125 | C8: 16 | D8: Document #16 — most significant single-document finding in corpus: Digital Evidence Subcommittee has zero identified R&D needs (entry 22) — strongest ORG-07 finding to date. ANSI/ASTM E3016-18 confidence standard (directly addresses confidence in digital evidence forensic results) has been pending OSAC registry acceptance since 2018 — strongest PRO-02 in corpus and direct empirical support for P2. First SWGDE documents entered OSAC Registry only in FY23 after nine years — confirms ORG-05 institutional siloing between NIST and SWGDE is not just a documentation issue but a structural governance gap. Cross-corpus pattern now clearly established: organizational awareness gap (ORG-07) + process deadlock on the one existing confidence standard (PRO-02) + first-ever cross-organizational registry integration only in 2023 (ORG-05) = three convergent barriers that collectively explain why digital forensics AI confidence measurement has not advanced to prescriptive standards. This is your P2 confirmation pattern. | E8: Document #16 — most significant single-document finding in corpus: Digital Evidence Subcommittee has zero identified R&D needs (entry 22) — strongest ORG-07 finding to date. ANSI/ASTM E3016-18 confidence standard (directly addresses confidence in digital evidence forensic results) has been pending OSAC registry acceptance since 2018 — strongest PRO-02 in corpus and direct empirical support for P2. First SWGDE documents entered OSAC Registry only in FY23 after nine years — confirms ORG-05 institutional siloing between NIST and SWGDE is not just a documentation issue but a structural governance gap. Cross-corpus pattern now clearly established: organizational awareness gap (ORG-07) + process deadlock on the one existing confidence standard (PRO-02) + first-ever cross-organizational registry integration only in 2023 (ORG-05) = three convergent barriers that collectively explain why digital forensics AI confidence measurement has not advanced to prescriptive standards. This is your P2 confirmation pattern. | F8: Document #16 — most significant single-document finding in corpus: Digital Evidence Subcommittee has zero identified R&D needs (entry 22) — strongest ORG-07 finding to date. ANSI/ASTM E3016-18 confidence standard (directly addresses confidence in digital evidence forensic results) has been pending OSAC registry acceptance since 2018 — strongest PRO-02 in corpus and direct empirical support for P2. First SWGDE documents entered OSAC Registry only in FY23 after nine years — confirms ORG-05 institutional siloing between NIST and SWGDE is not just a documentation issue but a structural governance gap. Cross-corpus pattern now clearly established: organizational awareness gap (ORG-07) + process deadlock on the one existing confidence standard (PRO-02) + first-ever cross-organizational registry integration only in 2023 (ORG-05) = three convergent barriers that collectively explain why digital forensics AI confidence measurement has not advanced to prescriptive standards. This is your P2 confirmation pattern. | G8: Document #16 — most significant single-document finding in corpus: Digital Evidence Subcommittee has zero identified R&D needs (entry 22) — strongest ORG-07 finding to date. ANSI/ASTM E3016-18 confidence standard (directly addresses confidence in digital evidence forensic results) has been pending OSAC registry acceptance since 2018 — strongest PRO-02 in corpus and direct empirical support for P2. First SWGDE documents entered OSAC Registry only in FY23 after nine years — confirms ORG-05 institutional siloing between NIST and SWGDE is not just a documentation issue but a structural governance gap. Cross-corpus pattern now clearly established: organizational awareness gap (ORG-07) + process deadlock on the one existing confidence standard (PRO-02) + first-ever cross-organizational registry integration only in 2023 (ORG-05) = three convergent barriers that collectively explain why digital forensics AI confidence measurement has not advanced to prescriptive standards. This is your P2 confirmation pattern.
A9: 6 | B9: 46125 | D9: change Code 1 from PRO-02 to PRO-06. Write a one-line decision log entry explaining: "E3016-18 is an SDO-published standard that has not been accepted into the OSAC governance registry — this is a coordination failure between ASTM and OSAC, not an internal process stall. PRO-06 is more precise than PRO-02." | E9: change Code 1 from PRO-02 to PRO-06. Write a one-line decision log entry explaining: "E3016-18 is an SDO-published standard that has not been accepted into the OSAC governance registry — this is a coordination failure between ASTM and OSAC, not an internal process stall. PRO-06 is more precise than PRO-02." | F9: change Code 1 from PRO-02 to PRO-06. Write a one-line decision log entry explaining: "E3016-18 is an SDO-published standard that has not been accepted into the OSAC governance registry — this is a coordination failure between ASTM and OSAC, not an internal process stall. PRO-06 is more precise than PRO-02." | G9: change Code 1 from PRO-02 to PRO-06. Write a one-line decision log entry explaining: "E3016-18 is an SDO-published standard that has not been accepted into the OSAC governance registry — this is a coordination failure between ASTM and OSAC, not an internal process stall. PRO-06 is more precise than PRO-02."
A10: 7 | B10: 2026-04-13 | C10: 36 | D10: Doc 36 dominant pattern: ORG-01 (scope exclusion) as primary frame — AI/confidence measurement excluded by design, not omission. TEC-01/TEC-02 present in preservation/collection sections without resolution. ORG-02 + PRO-02 co-occur in §9 confirming resource-process barrier dyad. Zero prescriptive confidence output. | E10: ORG-01 vs ORG-07: Doc 36 excludes AI by scope design (ORG-01), not because the organization lacks awareness (ORG-07) — scope exclusion is the more precise code here. | F10: Three SWGDE exclusion logics now confirmed: Doc 39 = informational positioning (ORG-01); Doc 38 = legal constraint (ORG-06); Doc 36 = operational scope (ORG-01). All produce zero prescriptive confidence output but via distinct institutional mechanisms. | G10: No new EMER codes required. ORG-02 + PRO-02 dyad in §9 is consistent with existing codebook. Flag for cross-document pattern analysis in final memo.
A11: 8 | B11: 2026-04-13 | C11: 42 | D11: Doc 42 dominant pattern: ORG-01 + ORG-06 dual exclusion in §3 now confirmed third consecutive SWGDE document (Docs #36, #38, #42). Hash verification (TEC-03/CRS-02) only integrity mechanism — contingent on provider cooperation. PRO-01: zero edits after public comment across 14-month cycle. Leanest codeable document in corpus. | E11: TEC-03 vs TEC-01: hash verification is an integrity check (TEC-03), not a confidence measurement gap (TEC-01) — no AI output being assessed here; distinction holds. | F11: ORG-01 + ORG-06 co-occurrence in §3 is now a confirmed SWGDE structural pattern across at least three documents. Cross-corpus pattern: SWGDE best practices documents open with dual scope/legal exclusion and produce zero prescriptive confidence output regardless of domain (IoT, cloud, facial recognition). | G11: No new EMER codes. Flag ORG-01+ORG-06 dyad as candidate theme node for P2 findings synthesis.
A12: 9 | B12: 46127 | C12: 34 | D12: Document-level pattern: ORG-01 (scope exclusion) + TEC-01 (measurement complexity) are co-dominant. TEC-02 present at §5. PRO-01 confirmed via revision history. No AI-specific content (publication date 2016). CRS-02 flags cluster around §3, §9, and §10.5/10.7 — competency/proficiency definitions acknowledge measurement without operationalizing it. | E12: Document-level pattern: ORG-01 (scope exclusion) + TEC-01 (measurement complexity) are co-dominant. TEC-02 present at §5. PRO-01 confirmed via revision history. No AI-specific content (publication date 2016). CRS-02 flags cluster around §3, §9, and §10.5/10.7 — competency/proficiency definitions acknowledge measurement without operationalizing it. | F12: Document-level pattern: ORG-01 (scope exclusion) + TEC-01 (measurement complexity) are co-dominant. TEC-02 present at §5. PRO-01 confirmed via revision history. No AI-specific content (publication date 2016). CRS-02 flags cluster around §3, §9, and §10.5/10.7 — competency/proficiency definitions acknowledge measurement without operationalizing it. | G12: Document-level pattern: ORG-01 (scope exclusion) + TEC-01 (measurement complexity) are co-dominant. TEC-02 present at §5. PRO-01 confirmed via revision history. No AI-specific content (publication date 2016). CRS-02 flags cluster around §3, §9, and §10.5/10.7 — competency/proficiency definitions acknowledge measurement without operationalizing it.
A13: 10 | B13: 46127 | C13: 6 | D13: Doc #6 is analytically the most important NIST document coded so far for your P1/P2 cross-phase integration. Three findings dominate. First, the technology-neutral design principle (Entry 67) is the most explicit institutional statement in the corpus of a design choice that produces the AIDFIR gap. It is not an oversight — it is an architectural decision. Second, RA-3(4) Predictive Cyber Analytics (Entry 68) is the sole AI-specific control enhancement in a 492-page document, and it prescribes human oversight as the AI reliability response rather than a validation protocol. Third, the assurance definition in §2.5 (Entry 65) establishes that confidence measurement is conceptually present in NIST's framework but deferred to SP 800-53A — a cross-document dependency that is itself a PRO-01 pattern. | E13: Entry 67 receives both ORG-01 and TEC-02 — these are not redundant. ORG-01 captures the institutional scope decision; TEC-02 captures the methodological consequence for AI validation. The CRS-01 flag at Entry 67 is warranted because the technology-neutral principle is the most direct statement of why AI-specific confidence guidance is absent. Entry 68 receives TEC-06 (first activation in a NIST document) alongside TEC-01 — the adversarial model retraining risk is an opacity/explainability problem before it is a measurement complexity problem. | F13: The validated-without-definition pattern at Entry 70 (SI-19(7)) is the federal-level analog of Doc #34's "validated technologies" requirement (SWGDE Entry 43). Both mandate validation as a principle; neither specifies a methodology. This cross-corpus parallel directly supports your TEC-02 finding. The PRO-01 errata pattern (Entry 71) continues the multi-document pattern: one revision cycle, editorial only, zero AI-specific content additions — now confirmed across NIST (Doc #6) and SWGDE (Docs #34, #42, #45) revision records. | G13: Doc #6 has higher D1 and D3 scores than most SWGDE documents (both score 2) because NIST conceptually addresses assurance and validation evidence. But D4 collapses both to 1 via the min-score rule. This is analytically important: NIST's greater conceptual sophistication on confidence and reproducibility makes the AI-specific gap more visible, not less. A document that knows what assurance means and still cannot provide AI-specific assurance guidance is a stronger demonstration of the gap than a document that never addresses the concept.
A14: 11 | B14: 46127 | C14: 10 | D14: Doc #10 is the most technically rich document in the corpus and produces the corpus's strongest TEC-01, TEC-04, and TEC-06 evidence. Three findings dominate. First, the mathematical impossibility argument (Entry 74): ML systems have no information-theoretic security proofs, which means AI confidence claims are structurally different from — and weaker than — the validated tool claims forensic examiners currently use. This is not a process gap but a theoretical one. Second, the risk tolerance non-recommendation (Entry 73): NIST explicitly names the concept forensic practitioners most need (when is AI risk acceptable?) and declines to answer it by design. Third, the benchmark incomparability finding (Entry 77): AI validation evidence is not merely sparse but structurally incomparable — results from different research groups cannot be aggregated because there are no standardized benchmarks. | E14: Entry 73 receives both ORG-01 and TEC-01. ORG-01 captures the institutional decision not to address risk tolerance; TEC-01 captures the technical rationale given (context-dependency). These are not redundant — the institutional decision could in principle be reversed even if the technical argument is valid. Entry 76 receives TEC-02 and TEC-06. The "ad hoc and fallible" characterization of mitigation design is TEC-02 (validation methodology gap); the inability to detect model compromise is TEC-06 (opacity barrier). Entry 78 receives TEC-01 and TEC-02 — the theoretical limits on testing are a measurement problem (TEC-01); the absence of specified measures beyond adversarial testing is a validation methodology gap (TEC-02). | F14: Doc #10 Entry 74 (no information-theoretic proofs for ML) provides the theoretical explanation for Doc #3 Entry 47 (measurement science "generally immature") and Doc #6 Entry 65 (assurance definition without operationalization). These three entries together form your complete theoretical-to-definitional-to-operational account of the D1 gap: immature measurement science (Doc #3) → formal proof impossibility (Doc #10) → assurance concept without method (Doc #6). The PRO-04 pattern at Entries 77 and 79 is the fourth document to close with deferral language — joining Doc #3 (Entry 55), Doc #13 (Entry 62), and Doc #6 (Entry 71). PRO-04 is now confirmed as a multi-document cross-organizational pattern, not a single-document artifact. | G14: Pareto constraint on confidence standards (Entry 75): The Pareto trade-off between accuracy, robustness, and fairness has not been explicitly theorized in prior corpus documents. This is the most technically sophisticated statement in the corpus of why a single-dimensional confidence metric cannot adequately validate a forensic AI tool. Consider whether this warrants a CRS sub-code or a memo-level observation that feeds into your cross-phase synthesis. | H14: Doc #10 scores 2 on all four dimensions — the first corpus document at that profile. This is analytically important: NIST AI 100-2 is the most AI-specific, most technically engaged document in the corpus, and it still cannot break above D4 = 2. The score of 2 reflects substantial conceptual engagement without prescriptive resolution. Your min-score rule appropriately captures this — 2 across all dimensions is a better outcome than 1 with a D4 ceiling, but it confirms that even the most sophisticated AI security documentation falls well short of the operational confidence measurement guidance your AIDFIR framework identifies as needed.
A15: 12 | B15: 46127 | C15: 4
A16: 13 | B16: 46127 | C16: 1 | D16: EMER-01 status: memo correctly says hold, do not activate. That decision stands. No action needed, but confirm you have a decision log entry written for this.
A17: 14 | B17: 46127 | C17: C1 | D17: Entry 16 (Doc C1) — ORG-03 provisional "?": Your memo notes this cannot be resolved without Doc C5 context. That is correctly flagged. No action now — but add a cross-reference note in your memo column pointing to "resolve pending C5 coding."
A18: 15 | B18: 46128 | C18: 7 | D18: Document-Level Pattern Note (Doc #7) Doc #7 presents a distinctive and analytically significant pattern not previously seen in the corpus: it is the only document where the revision history documents a deliberate retreat from prescriptive operational content. The ORG-01 + PRO-03 co-occurrence at entries 92 and 97 is reinforced by the explicit Change Log, which constitutes institutional documentary evidence — not inference — that the AIDFIR-relevant content space was actively narrowed. The CRS-01 flag at entry 95 (sole AI reference, parenthetical) confirms that by 2025, a major NIST incident response publication still had not integrated AI-specific guidance despite clear operational relevance. Together these entries contribute a third barrier logic to the NIST SP 800 sub-corpus alongside the voluntary-framing ORG-01 (Docs #3, #6, #10) and hub-and-spoke PRO-06 (Docs #4, #5): active prescriptive retraction. New codes generated: 0. All codes used (ORG-01, ORG-07, TEC-01, TEC-02, PRO-03, PRO-06, CRS-01, CRS-02, ORG-06) are existing codebook entries. Update saturation tracker accordingly.
